<robot name="2_R_robot">

<link name="fixed_base">

      <visual>
         <geometry>
            <sphere radius = "0.075"/>
         </geometry>
         <material name = "black">
            <color rgba="0 0 0 1"/>
         </material>
         <origin rpy="0 0 0" xyz="0 0 0"/>
      </visual>

   </link>


   <link name="link_1">

      <visual>
         <geometry>
            <cylinder radius="0.03" length="0.5"/>
         </geometry>
         <material name = "cyan">
            <color rgba="0 1 1 1"/>
         </material>
         <origin xyz="0 0 0.25" rpy="0 0 0"/>
      </visual>

   </link>


   <link name="link_2">

      <visual>
         <geometry>
            <cylinder radius="0.03" length="0.5"/>
         </geometry>
         <material name = "yellow">
            <color rgba="1 1 0 1"/>
         </material>
         <origin xyz="0 0 0.25" rpy="0 0 0"/>
      </visual>
   </link>


   <!-- <link name="link_3">

      <visual>
         <geometry>
            <cylinder radius="0.03" length="0.5"/>
         </geometry>
         <origin xyz="0 0 0.25" rpy="0 0 0"/>
      </visual>

   </link> -->


   <joint name="Revolute_joint_1" type="revolute">

      <parent link="fixed_base"/>
      <child link="link_1"/>
      <limit upper="3.14" lower="-3.14"/>
      <origin xyz = "0 0 0" rpy="0 0 0"/>
      <axis xyz="1 0 0"/>

   </joint>


   <joint name="Revolute_joint_2" type="revolute">

      <parent link="link_1"/>
      <child link="link_2"/>
      <limit upper="2.5" lower="-2.5"/>
      <origin xyz = "0 0 0.5" rpy="0 0 0"/>
      <axis xyz="1 0 0"/>

   </joint>


   <!-- <joint name="Revolute_joint_3" type="revolute">

      <parent link="link_2"/>
      <child link="link_3"/>
      <limit upper="2.5" lower="-2.5"/>
      <origin xyz = "0 0 0.5" rpy="0 0 0"/>
      <axis xyz="1 0 0"/>

   </joint>  -->


</robot>